[2025-03-20T16:18:13.799+0000] {taskinstance.py:1159} INFO - Dependencies all met for dep_context=non-requeueable deps ti=<TaskInstance: dimension_ingestion_gcs_dag.cards_load_to_gcp scheduled__2025-03-20T16:17:30.515598+00:00 [queued]>
[2025-03-20T16:18:13.821+0000] {taskinstance.py:1159} INFO - Dependencies all met for dep_context=requeueable deps ti=<TaskInstance: dimension_ingestion_gcs_dag.cards_load_to_gcp scheduled__2025-03-20T16:17:30.515598+00:00 [queued]>
[2025-03-20T16:18:13.821+0000] {taskinstance.py:1361} INFO - Starting attempt 1 of 1
[2025-03-20T16:18:13.848+0000] {taskinstance.py:1382} INFO - Executing <Task(PythonOperator): cards_load_to_gcp> on 2025-03-20 16:17:30.515598+00:00
[2025-03-20T16:18:13.861+0000] {standard_task_runner.py:57} INFO - Started process 9622 to run task
[2025-03-20T16:18:13.869+0000] {standard_task_runner.py:84} INFO - Running: ['***', 'tasks', 'run', 'dimension_ingestion_gcs_dag', 'cards_load_to_gcp', 'scheduled__2025-03-20T16:17:30.515598+00:00', '--job-id', '127', '--raw', '--subdir', 'DAGS_FOLDER/etl_ingest_tables.py', '--cfg-path', '/tmp/tmpes94sh4u']
[2025-03-20T16:18:13.875+0000] {standard_task_runner.py:85} INFO - Job 127: Subtask cards_load_to_gcp
[2025-03-20T16:18:13.957+0000] {task_command.py:415} INFO - Running <TaskInstance: dimension_ingestion_gcs_dag.cards_load_to_gcp scheduled__2025-03-20T16:17:30.515598+00:00 [running]> on host 2c8eeef746cb
[2025-03-20T16:18:14.096+0000] {taskinstance.py:1660} INFO - Exporting env vars: AIRFLOW_CTX_DAG_OWNER='***' AIRFLOW_CTX_DAG_ID='dimension_ingestion_gcs_dag' AIRFLOW_CTX_TASK_ID='cards_load_to_gcp' AIRFLOW_CTX_EXECUTION_DATE='2025-03-20T16:17:30.515598+00:00' AIRFLOW_CTX_TRY_NUMBER='1' AIRFLOW_CTX_DAG_RUN_ID='scheduled__2025-03-20T16:17:30.515598+00:00'
[2025-03-20T16:18:14.115+0000] {taskinstance.py:1943} ERROR - Task failed with exception
Traceback (most recent call last):
  File "/home/airflow/.local/lib/python3.9/site-packages/airflow/operators/python.py", line 192, in execute
    return_value = self.execute_callable()
  File "/home/airflow/.local/lib/python3.9/site-packages/airflow/operators/python.py", line 209, in execute_callable
    return self.python_callable(*self.op_args, **self.op_kwargs)
  File "/opt/airflow/dags/gcp_operations.py", line 28, in upload_single_file_to_gcs
    blob.upload_from_filename(local_file)
  File "/home/airflow/.local/lib/python3.9/site-packages/google/cloud/storage/blob.py", line 2682, in upload_from_filename
    with open(filename, "rb") as file_obj:
IsADirectoryError: [Errno 21] Is a directory: '/opt/airflow/temp_data/trnsction/trnsction'
[2025-03-20T16:18:14.138+0000] {taskinstance.py:1400} INFO - Marking task as FAILED. dag_id=dimension_ingestion_gcs_dag, task_id=cards_load_to_gcp, execution_date=20250320T161730, start_date=20250320T161813, end_date=20250320T161814
[2025-03-20T16:18:14.165+0000] {standard_task_runner.py:104} ERROR - Failed to execute job 127 for task cards_load_to_gcp ([Errno 21] Is a directory: '/opt/airflow/temp_data/trnsction/trnsction'; 9622)
[2025-03-20T16:18:14.201+0000] {local_task_job_runner.py:228} INFO - Task exited with return code 1
[2025-03-20T16:18:14.237+0000] {taskinstance.py:2784} INFO - 0 downstream tasks scheduled from follow-on schedule check
